Workbook
Name Electric: Reference!$D$2:$D$2
Name Motor___Cooling: Reference!$C$2:$C$2
Name Packing: Reference!$A$1:$A$3
Name Plastic: Reference!$B$2:$B$3

Sheet Qm-ValidationPredict
B2: Which Quarter:
B3: 12
B4: For:
B5: Validation
B6: Overtime?
B7: {=INDIRECT("'Input_Q"&B3&"-Predict'!C8")} -> Overtime
B9: From last Quarter
B10: Decicion Point
B11: Prediction
B14: 1. Operation
B16: Cost Overview
B17: Plant | C17: 0 | E17: Note: Raw material cost including the shipping fee related to each part
B18: Research & Development | C18: =F19*F20 -> 135000 | E18: Operation Cost Datasheet | I18: Q3 Order | K18: Type | L18: Unit Cost+Shipping | M18: Climatizer unit cost | N18: Order cost
B19: Raw Material | C19: =N23 -> 0 | E19: R&D | F19: 15000 | G19: /unit | J19: Packing | K19: Premium | L19: =VLOOKUP($K$19,$E$24:F59,2,FALSE) -> 36 | M19: =L19*$F$25 -> 36 | N19: =M19*$F$24 -> 0
B20: Raw Material Storage Costs | C20: =C34*0.02*M24 -> 1136.0868 | F20: {=INDIRECT("'Input_Q"&B3&"-Predict'!C38")} -> 9 | I20: Decision | J20: Plastic | K20: Superplast | L20: =VLOOKUP($K$20,$E$25:F60,2,FALSE) -> 44.52 | M20: =L20*$F$28 -> 89.04 | N20: =M20*$F$24 -> 0
B21: Production Fixed Cost | C21: 280000 | E21: MachineryModel | J21: Motor & Cooling | K21: Freezpro | L21: =VLOOKUP($K$21,$E$26:F63,2,FALSE) -> 187.2 | M21: =L21*$F$38 -> 374.4 | N21: =M21*$F$24 -> 0
C22: =SUM(C17:C21) -> 416136.09 | E22: Model1 | F22: 1300000 | J22: Electric | K22: Proline | L22: =VLOOKUP($K$22,$E$21:F60,2,FALSE) -> 24.15 | M22: =L22*$F$51 -> 72.45 | N22: =M22*$F$24 -> 0
E23: Model2 | F23: 1500000 | I23: unit climatizer cost | M23: =SUM(M19:M22) -> 571.89 | N23: =SUM(N19:N22) -> 0
E24: Raw Material | F24: {=INDIRECT("'Input_Q"&B3&"-Predict'!C36")} -> 0 | G24: # of climatizer RM | I24: Unit Value | M24: =M23-M19 -> 535.89 | N24: =M24*F24 -> 0
B25: Productivity | C25: {=IF(B5="Validation",'Qm-ValidationPredict'!C30/'Qm-ValidationPredict'!C29,INDIRECT("'Input_Q"&B3&"-Predict'!C34"))} -> 0.97019957 | E25: Packing | F25: 1 | G25: unit/climatizer
E26: Standard | F26: 20
B27: Climatizer Stock | C27: =INDEX(Data_Stock!B2:N11,MATCH("Left Inventory",Data_Stock!B2:B11,0),MATCH(VALUE(B3-1),Data_Stock!B2:N2,0)) -> 90 | E27: Premium | F27: 36
B28: Raw Material Available | C28: =INDEX(Data_Stock!B2:N11,MATCH("Left",Data_Stock!B2:B11,0),MATCH(VALUE(B3-1),Data_Stock!B2:N2,0)) -> 1545 | E28: Plastic | F28: 2 | G28: unit/climatizer
B29: Planned Production | C29: {=INDIRECT("'Input_Q"&B3&"-Predict'!C33")} -> 1483.2 | E29: Plastinjet | F29: =(1+F31)*F30 -> 43.2
B30: =IF(B5="Validation","Actual Production","Predict Production") -> Actual Production | C30: =INDEX(Data_Stock!B2:N11,MATCH("Produced",Data_Stock!B2:B11,0),MATCH(VALUE(B3),Data_Stock!B2:N2,0)) -> 1439 | E30: material | F30: 40
E31: Shipping | F31: 0.08
B32: Raw Material Left | E32: Superplast | F32: =(1+F34)*F33 -> 44.52
B33: Raw Material Purchased | C33: =F24 -> 0 | E33: material | F33: 42
B34: Raw Material Available for Q+1 | C34: =IF(B5="Validation",INDEX(Data_Stock!B2:N11,MATCH("Left",Data_Stock!B2:B11,0),MATCH('Qm-ValidationPredict'!B3,Data_Stock!B2:N2,0)),C28+F24-C30) -> 106 | E34: Shipping | F34: 0.06
B35: Total Inventory Value | C35: =C34*M24 -> 56804.34 | E35: IPLM | F35: =(1+F37)*F36 -> 56.1
E36: material | F36: 55
E37: Shipping | F37: 0.02
E38: Moter&Cooling | F38: 2 | G38: unit/climatizer
E39: Motojister | F39: =(1+F41)*F40 -> 117.7
E40: material | F40: 110
E41: Shipping | F41: 0.07
E42: Motormaster | F42: =(1+F44)*F43 -> 186.3
E43: material | F43: 162
E44: Shipping | F44: 0.15
E45: InfinityParts | F45: =(1+F47)*F46 -> 193.6
...

Sheet Archive-Input_Qm-Predict
C1: Preparasion for next quarter prediction
B2: TRUE | C2: 1. Validate data from previous quarter ( By QingQing)
B3: FALSE | C3: 2. Update Data_ Sheets( Need cash flow update By Seb)
B4: FALSE | C4: 3.Create new prediction sheet for new quarter+ Validation ( QingQing)
B5: FALSE | C5: 4. Choose the Number of current quarter in B6
B6: Quarter | C6: 7
B7: Strategy | C7: Maximum Capacity | E7: Note: Conservasive strategy have a constrain which will only keep the next quarter RM unit =1200
B8: Working Hour | C8: Overtime
B9: SalePrice
B10: 1 | C10: 2899
B11: 2 | C11: 2399
B12: 3 | C12: 2899
B13: 4 | C13: 2899
B14: NET PROFIT / LOSS | C14: {=INDIRECT("'Q"&C6&"-Predict'!C149")} -> 121140.48
B15: PROFIT AND LOSS STATEMENT RESULTS | C15: {=INDIRECT("'Q"&C6&"-Predict'!C154")} -> -470423.89
B17: Previous Quarter balance | C17: =INDEX(Data_IncomeStatement!A1:M33,MATCH("PROFIT AND LOSS STATEMENT RESULTS", Data_IncomeStatement!A1:A33, 0),MATCH(VALUE(C6-1), Data_IncomeStatement!A1:M1, 0)) -> -591564.37 | D17: DO NOT CHANGE THIS CELL!! | I17: Revenue | J17: Predicted sale*price
B18: Loan interest | C18: 0 | D18: C139 | E18: Given | I18: Price | J18: COGS
B19: Climatizer Stock | C19: =INDEX(Data_Stock!B2:N11,MATCH("Left Inventory",Data_Stock!B2:B11,0),MATCH(VALUE(C6-1),Data_Stock!B2:N2,0)) -> 25 | D19: DO NOT CHANGE THIS CELL!! | E19: Given | G19: =819+741-960 -> 600 | J19: 1. Predicted sale unit * raw material cost
B20: Raw Material Available | C20: =INDEX(Data_Stock!B2:N11,MATCH("Left",Data_Stock!B2:B11,0),MATCH(VALUE(C6-1),Data_Stock!B2:N2,0)) -> 1632 | D20: DO NOT CHANGE THIS CELL!! | E20: Given | J20: 2. Revenue *( Commision + 0.125)
B21: Maximum Sell unit | C21: =IF(C8="Overtime",MIN((1500*C34+C19),(C19+(C20*C34))),MIN((1200*C34+C19),(C19+(C20*C34)))) -> 1465
B22: Plan to Sell | C22: =C21 -> 1465 | E22: # Prediction based on the demand
B23: ="----------------------------------------------->>" -> ----------------------------------------------->> | C23: =MIN(C22,C21) -> 1465 | D23: DO NOT CHANGE THIS CELL!! | E23: #Capped by the maximum sell unit | J23: Fixed cost
B24: 1 | C24: =ROUNDDOWN($C$23*D24,0) -> 439 | D24: 0.3 | E24: # Plan to have more market share | J24: 1. 280000
B25: 2 | C25: =ROUNDDOWN($C$23*D25,0) -> 249 | D25: 0.17 | E25: # Focus | J25: 2. Loan Interest
B26: 3 | C26: =ROUNDDOWN($C$23*D26,0) -> 43 | D26: =1-D27-D25-D24 -> 0.03 | J26: 2. R&D investment
B27: 4 | C27: =ROUNDDOWN($C$23*D27,0) -> 732 | D27: 0.5 | E27: # Leader | J27: 3. Report to purchase
B28: Predicted Sale | C28: =SUM(C29:C32) -> 1014 | D28: Based on the predicted conversion rate | J28: 4. Raw material inventory (new purchase + left after production)
B29: 1 | C29: =ROUNDDOWN(C24*D29,0) -> 307 | D29: 0.7 | E29: 1613 | F29: =C29/E29 -> 0.19032858 | J29: 5. A&P
B30: 2 | C30: =ROUNDDOWN(C25*D30,0) -> 174 | D30: 0.7 | E30: 1094 | F30: =C30/E30 -> 0.15904936 | J30: 6. Total salary
B31: 3 | C31: =ROUNDDOWN(C26*D31,0) -> 21 | D31: 0.5 | E31: 1210 | F31: =C31/E31 -> 0.017355372
B32: 4 | C32: =ROUNDDOWN(C27*D32,0) -> 512 | D32: 0.7 | E32: 1843 | F32: =C32/E32 -> 0.27780792
B33: Plan to produce | C33: =C23-C19 -> 1440 | E33: # = plan to sale - finish good stock
B34: Productivity | C34: 0.96
B35: Predicted Produced | C35: =ROUNDDOWN(C33*C34,0) -> 1382
B36: Raw Material to purchase | C36: 1500
B37: ="------------------------------->" -> -------------------------------> | C37: =IF(C7="Conservasive",1200-(C20-C35),C36) -> 1500 | E37: # = 1200 - (Raw material available - real produce)
B38: R&D | C38: 9
B39: Commision | C39: 0.06
B40: Advertisement
B41: 1 | C41: 7 | D41: ='Q7-Predict'!F75 -> 89086.27
...

Sheet Input_Qm-Predict
B1: Preparasion for next quarter prediction
B2: TRUE | C2: 1. Validate data from previous quarter ( By QingQing)
B3: FALSE | C3: 2. Update Data_ Sheets( Need cash flow update By Seb)
B4: FALSE | C4: 3.Create new prediction sheet for new quarter+ Validation ( QingQing)
B5: FALSE | C5: 4. Choose the Number of current quarter in B6
B6: Quarter | C6: 12
B7: Strategy | C7: Maximum Capacity | E7: Note: Conservative strategy have a constrain which will only keep the next quarter RM unit =1200
B8: Working Hour | C8: Overtime
B9: SalePrice | E9: Predicted Sale
B10: 1 | C10: 2899 | E10: =C28 -> 626
B11: 2 | C11: 2399 | E11: BreakEven unit
B12: 3 | C12: 2899 | E12: {=INDIRECT("'Q"&C6&"-Predict'!C165")} -> 1357
B13: 4 | C13: 2899 | E13: =IF(E12>E10,"Need Adjustment","All Good") -> Need Adjustment
B14: NET PROFIT / LOSS | C14: {=INDIRECT("'Q"&C6&"-Predict'!C149")} -> 71587.377
B15: PROFIT AND LOSS STATEMENT RESULTS | C15: {=INDIRECT("'Q"&C6&"-Predict'!C154")} -> 1998746.5
B17: Previous Quarter balance | C17: =INDEX(Data_IncomeStatement!A1:M33,MATCH("PROFIT AND LOSS STATEMENT RESULTS", Data_IncomeStatement!A1:A33, 0),MATCH(VALUE(C6-1), Data_IncomeStatement!A1:M1, 0)) -> 1927159.1 | E17: DO NOT CHANGE THIS CELL!!
B18: Loan interest | C18: 0 | E18: Given
B19: Climatizer Stock | C19: =INDEX(Data_Stock!B2:N11,MATCH("Left Inventory",Data_Stock!B2:B11,0),MATCH(VALUE(C6-1),Data_Stock!B2:N2,0)) -> 90 | E19: DO NOT CHANGE THIS CELL!!
B20: Raw Material Available | C20: =INDEX(Data_Stock!B2:N11,MATCH("Left",Data_Stock!B2:B11,0),MATCH(VALUE(C6-1),Data_Stock!B2:N2,0)) -> 1545 | E20: DO NOT CHANGE THIS CELL!!
B21: Maximum Sell unit | C21: =IF(C8="Overtime",MIN((1560*C34+C19),(C19+(C20*C34))),MIN((1200*C34+C19),(C19+(C20*C34)))) -> 1573.2
B22: Plan to Sell | C22: =C21 -> 1573.2 | E22: # Prediction based on the demand
B23: ="----------------------------------------------->>" -> ----------------------------------------------->> | C23: =MIN(C22,C21) -> 1573.2 | D23: Proportion | E23: #Capped by the maximum sell unit
B24: 1 | C24: =ROUNDDOWN($C$23*D24,0) -> 471 | D24: 0.3 | E24: # Plan to have more market share
B25: 2 | C25: =ROUNDDOWN($C$23*D25,0) -> 267 | D25: 0.17 | E25: # Focus
B26: 3 | C26: =ROUNDDOWN($C$23*D26,0) -> 47 | D26: =1-D27-D25-D24 -> 0.03
B27: 4 | C27: =ROUNDDOWN($C$23*D27,0) -> 786 | D27: 0.5 | E27: # Leader
B28: Predicted Sale | C28: =SUM(C29:C32) -> 626 | D28: Proportion | E28: #Based on the predicted conversion rate
B29: 1 | C29: =ROUNDDOWN(C24*D29,0) -> 188 | D29: 0.4
B30: 2 | C30: =ROUNDDOWN(C25*D30,0) -> 106 | D30: 0.4
B31: 3 | C31: =ROUNDDOWN(C26*D31,0) -> 18 | D31: 0.4
B32: 4 | C32: =ROUNDDOWN(C27*D32,0) -> 314 | D32: 0.4
B33: Plan to produce | C33: =C23-C19 -> 1483.2 | E33: # = plan to sale - finish good stock
B34: Productivity | C34: 0.96
B35: Predicted Produced | C35: =ROUNDDOWN(C33*C34,0) -> 1423
B36: Raw Material to purchase | C36: 1500
B37: ="------------------------------->" -> -------------------------------> | C37: =IF(C7="Conservasive",1200-(C20-C35),C36) -> 1500 | E37: # = 1200 - (Raw material available - real produce)
B38: R&D | C38: 9
B39: Commision | C39: 0.06
B40: Advertisement | C40: Level
B41: 1 | C41: 7
...

Sheet Read Me
A1: The comprehensive manual can be found in the other document.
A3: Sheet Name | B3: Description
A4: Qm-ValidationPredict | B4: Template for Validation or Prediction
A5: Input_Qm-Predict | B5: Decision points input for prediction period
A6: DashBoard | B6: Overview performance--Income statement, market share, stock
A7: Reference | B7: Cell reference
A8: Pricing-Working
A9: Information-Working
A10: Data- | B10: Data Sheets Containing our Data Price, Sales, CashFlows, Stock, IS, Emp #.
A11: Q12-Validation | B11: Q# Validation Reports - Inputting Results
A12: Q12-Predict | B12: Q# Prediction Reports - Forecasted Results
A13: Input_Q12-Predict
A14: Q11-Validation
A15: Q11-Predict
A16: Input_Q11-Predict
A17: Input_Q10-Predict
A18: Q10-Validation
A19: Q10-Predict
A20: Q9-Validation
A21: Input_Q9-Predict
A22: Q9-Predict
A23: Q8-Validation
A24: Input_Q8-Predict
... A40: Q1-Data

Sheet Dashboard
B3: Sales Per Region | R3: Market Share Per Region - Purchased for Quarter 3 | AI3: Income Statements Per Quarter
B5: Sales | AZ5: Inventory Flow
C6: Q1 | D6: Q2 | E6: Q3 | F6: Q4 | G6: Q5 | H6: Q6 | I6: Q7 | J6: Q8 | K6: Q9 | L6: Q10 | M6: Q11 | N6: Q12 | V6: Market Share | W6: Region 1 | X6: Region 2 | Y6: Region 3 | Z6: Region 4 | AJ6: Q1 | AK6: Q2 | AL6: Q3 | AM6: Q4 | AN6: Q5 | AO6: Q6 | AP6: Q7 | AQ6: Q8 | AR6: Q9 | AS6: Q10 | AT6: Q11 | AU6: Q12 | AZ6: Raw Materials | BA6: Q1 | BB6: Q2 | BC6: Q3 | BD6: Q4 | BE6: Q5 | BF6: Q6 | BG6: Q7 | BH6: Q8 | BI6: Q9 | BJ6: Q10 | BK6: Q11 | BL6: Q12
B7: Region 1 | C7: 0 | D7: 50 | E7: 99 | F7: 210 | G7: 292 | H7: 150 | I7: 359 | J7: 264 | K7: 427 | L7: 484 | M7: 577 | N7: 403 | V7: EcoChill | W7: 0.5533 | X7: 0 | Y7: 0.1664 | Z7: 0.1392 | AI7: Sales Income | AJ7: ='Q1'!B90 -> 0 | AK7: ='Q2'!B111 -> 798556 | AL7: ='Q3-Validation'!C123 -> 1923112 | AM7: ='Q4-Validation'!C123 -> 1686105 | AN7: ='Q5-Validation'!C123 -> 3489303 | AO7: ='Q6-Validation'!$C$123 -> 2554023 | AP7: ='Q7-Validation'!C123 -> 3616316 | AQ7: ='Q8-Validation'!C123 -> 2792036 | AR7: ='Q9-Validation'!C123 -> 4158295 | AS7: ='Q10-Validation'!C123 -> 4562295 | AT7: ='Q11-Validation'!C123 -> 5265050 | AU7: ='Q12-Validation'!C123 -> 3728892 | AZ7: Used in Production | BA7: 0 | BB7: 1128 | BC7: 1134 | BD7: 1134 | BE7: 750 | BF7: 924 | BG7: 1382 | BH7: 1382 | BI7: 1498 | BJ7: 1498 | BK7: 1513 | BL7: 1439
B8: Region 2 | C8: 0 | D8: 103 | E8: 216 | F8: 79 | G8: 297 | H8: 301 | I8: 212 | J8: 198 | K8: 271 | L8: 302 | M8: 327 | N8: 210 | V8: EcoBreeze | W8: 0.1134 | X8: 0.3501 | Y8: 0.3103 | Z8: 0.5833 | AI8: COGS | AJ8: ='Q1'!B91 -> 0 | AK8: ='Q2'!B112 -> 423285.9 | AL8: ='Q3-Validation'!C124 -> 1045048.8 | AM8: ='Q4-Validation'!C124 -> 791550.97 | AN8: ='Q5-Validation'!C124 -> 1444533.1 | AO8: ='Q6-Validation'!$C$124 -> 996058.8 | AP8: ='Q7-Validation'!C124 -> 1357101.2 | AQ8: ='Q8-Validation'!C124 -> 1033124.6 | AR8: ='Q9-Validation'!C124 -> 1575799 | AS8: ='Q10-Validation'!C124 -> 1761908 | AT8: ='Q11-Validation'!C124 -> 1965430.8 | AU8: ='Q12-Validation'!C124 -> 1390789.1 | AZ8: Purchased | BA8: 1200 | BB8: 1200 | BC8: 1200 | BD8: 1062 | BE8: 675 | BF8: 1500 | BG8: 1500 | BH8: 1500 | BI8: 1560 | BJ8: 1560 | BK8: 1066 | BL8: 0
B9: Region 3 | C9: 0 | D9: 66 | E9: 207 | F9: 121 | G9: 117 | H9: 25 | I9: 39 | J9: 50 | K9: 48 | L9: 151 | M9: 57 | N9: 40 | V9: Loll | W9: 0.1523 | X9: 0.2334 | Y9: 0.1169 | Z9: 0.1619 | AI9: Gross Profit and Loss | AJ9: ='Q1'!B92 -> 0 | AK9: ='Q2'!B113 -> 375270.1 | AL9: ='Q3-Validation'!C125 -> 878063.22 | AM9: ='Q4-Validation'!C125 -> 894554.03 | AN9: ='Q5-Validation'!C125 -> 2044769.9 | AO9: ='Q6-Validation'!$C$125 -> 1557964.2 | AP9: ='Q7-Validation'!C125 -> 2259214.8 | AQ9: ='Q8-Validation'!C125 -> 1758911.4 | AR9: ='Q9-Validation'!C125 -> 2582496 | AS9: ='Q10-Validation'!C125 -> 2800387 | AT9: ='Q11-Validation'!C125 -> 3299619.2 | AU9: ='Q12-Validation'!C125 -> 2338102.9 | AZ9: Left | BA9: 1200 | BB9: =BB8+BA9-BB7 -> 1272 | BC9: =BC8+BB9-BC7 -> 1338 | BD9: =BD8+BC9-BD7 -> 1266 | BE9: =BE8+BD9-BE7 -> 1191 | BF9: =BF8+BE9-BF7 -> 1767 | BG9: =BG8+BF9-BG7 -> 1885 | BH9: =BH8+BG9-BH7 -> 2003 | BI9: =BI8+BH9-BI7 -> 2065 | ... BL9: =BL8+BK9-BL7 -> 241
B10: Region 4 | C10: 0 | D10: 325 | E10: 616 | F10: 485 | G10: 785 | H10: 501 | I10: 674 | J10: 452 | K10: 759 | L10: 668 | M10: 889 | N10: 655 | V10: NorthBreeze | W10: =1-SUM(W7:W9) -> 0.181 | X10: =1-SUM(X7:X9) -> 0.4165 | Y10: =1-SUM(Y7:Y9) -> 0.4064 | Z10: =1-SUM(Z7:Z9) -> 0.1156 | AZ10: Finished Goods
B11: Freight Cost | D11: 23490 | E11: 47968 | F11: 41370 | G11: 61890 | H11: 36058 | I11: 55012 | J11: 38776 | K11: 63022 | L11: 64144 | M11: 76922 | N11: 55710 | AI11: Production Fixed Cost | AJ11: ='Q1'!B94 -> 280000 | AK11: ='Q2'!B115 -> 280000 | AL11: ='Q3-Validation'!C127 -> 280000 | AM11: ='Q4-Validation'!C127 -> 280000 | AN11: ='Q5-Validation'!C127 -> 280000 | AO11: ='Q6-Validation'!$C$127 -> 280000 | AP11: ='Q7-Validation'!C127 -> 560000 | AQ11: ='Q8-Validation'!C127 -> 560000 | AR11: ='Q9-Validation'!C127 -> 560000 | AS11: ='Q10-Validation'!C127 -> 560000 | AT11: ='Q11-Validation'!C127 -> 560000 | AU11: ='Q12-Validation'!C127 -> 560000 | AZ11: Produced | BA11: =BA7 -> 0 | BB11: =BB7 -> 1128 | BC11: =BC7 -> 1134 | BD11: =BD7 -> 1134 | BE11: =BE7 -> 750 | BF11: =BF7 -> 924 | BG11: =BG7 -> 1382 | BH11: =BH7 -> 1382 | ... BL11: =BL7 -> 1439
AI12: Salaries | AJ12: ='Q1'!B95 -> 267500 | AK12: ='Q2'!B116 -> 272500 | AL12: ='Q3-Validation'!C128 -> 282500 | AM12: ='Q4-Validation'!C128 -> 287500 | AN12: ='Q5-Validation'!C128 -> 304200 | AO12: ='Q6-Validation'!$C$128 -> 304200 | AP12: ='Q7-Validation'!C128 -> 608400 | AQ12: ='Q8-Validation'!C128 -> 608400 | AR12: ='Q9-Validation'!C128 -> 608400 | AS12: ='Q10-Validation'!C128 -> 608400 | AT12: ='Q11-Validation'!C128 -> 608400 | AU12: ='Q12-Validation'!C128 -> 608400 | AZ12: Available to sell | BA12: 0 | BB12: =BA14+BB11 -> 1128 | BC12: =BB14+BC11 -> 1718 | BD12: =BC14+BD11 -> 1714 | BE12: 1600 | BF12: 1600 | BG12: 1600 | BH12: 1600 | BI12: 1600 | BJ12: 1600 | BK12: 1925 | BL12: 1573
AI13: Training Investments | AJ13: ='Q1'!B96 -> 20000 | AK13: ='Q2'!B117 -> 30000 | AL13: ='Q3-Validation'!C129 -> 40000 | AM13: ='Q4-Validation'!C129 -> 40000 | AN13: ='Q5-Validation'!C129 -> 70000 | AO13: ='Q6-Validation'!$C$129 -> 70000 | AP13: ='Q7-Validation'!C129 -> 70000 | AQ13: ='Q8-Validation'!C129 -> 70000 | AR13: ='Q9-Validation'!C129 -> 70000 | AS13: ='Q10-Validation'!C129 -> 70000 | AT13: ='Q11-Validation'!C129 -> 50000 | AU13: ='Q12-Validation'!C129 -> 50000 | AZ13: Sold | BA13: 0 | BB13: 544 | BC13: 1138 | BD13: 895 | BE13: 1491 | BF13: 977 | BG13: 1284 | BH13: 964 | BI13: 1505 | BJ13: 1605 | BK13: 1850 | BL13: 1308
AI14: Fringe Benefits Investments | AJ14: ='Q1'!B97 -> 52425 | AK14: ='Q2'!B118 -> 53590 | AL14: ='Q3-Validation'!C130 -> 55920 | AM14: ='Q4-Validation'!C130 -> 57085 | AN14: ='Q5-Validation'!C130 -> 47000 | AO14: ='Q6-Validation'!$C$130 -> 47000 | AP14: ='Q7-Validation'!C130 -> 47000 | AQ14: ='Q8-Validation'!C130 -> 47000 | AR14: ='Q9-Validation'!C130 -> 47000 | AS14: ='Q10-Validation'!C130 -> 47000 | AT14: ='Q11-Validation'!C130 -> 47000 | AU14: ='Q12-Validation'!C130 -> 47000 | AZ14: Left Inventory | BA14: =BA12-BA13 -> 0 | BB14: =BB12-BB13 -> 584 | BC14: =BC12-BC13 -> 580 | BD14: =BD12-BD13 -> 819 | BE14: =BE12-BE13 -> 109 | BF14: =BF12-BF13 -> 623 | BG14: =BG12-BG13 -> 316 | BH14: =BH12-BH13 -> 636 | ... BL14: =BL12-BL13 -> 265
AI15: CSR. Investments | AJ15: ='Q1'!B98 -> 4000 | AK15: ='Q2'!B119 -> 4000 | AL15: ='Q3-Validation'!C131 -> 8000 | AM15: ='Q4-Validation'!C131 -> 8000 | AN15: ='Q5-Validation'!C131 -> 10000 | AO15: ='Q6-Validation'!$C$131 -> 10000 | AP15: ='Q7-Validation'!C131 -> 10000 | AQ15: ='Q8-Validation'!C131 -> 10000 | AR15: ='Q9-Validation'!C131 -> 18000 | AS15: ='Q10-Validation'!C131 -> 18000 | AT15: ='Q11-Validation'!C131 -> 18000 | AU15: ='Q12-Validation'!C131 -> 18000
AI16: Profit Sharing Payment | AJ16: ='Q1'!B99 -> 0 | AK16: ='Q2'!B120 -> 0 | AL16: ='Q3-Validation'!C132 -> 0 | AM16: ='Q4-Validation'!C132 -> 0 | AN16: ='Q5-Validation'!C132 -> 0 | AO16: ='Q6-Validation'!$C$132 -> 0 | AP16: ='Q7-Validation'!C132 -> 0 | AQ16: ='Q8-Validation'!C132 -> 0 | AR16: ='Q9-Validation'!C132 -> 0 | AS16: ='Q10-Validation'!C132 -> 0 | AT16: ='Q11-Validation'!C132 -> 0 | AU16: ='Q12-Validation'!C132 -> 0
AI17: Research & Development | AJ17: ='Q1'!B100 -> 30000 | AK17: ='Q2'!B121 -> 45000 | AL17: ='Q3-Validation'!C133 -> 75000 | AM17: ='Q4-Validation'!C133 -> 75000 | AN17: ='Q5-Validation'!C133 -> 135000 | AO17: ='Q6-Validation'!$C$133 -> 135000 | AP17: ='Q7-Validation'!C133 -> 135000 | AQ17: ='Q8-Validation'!C133 -> 135000 | AR17: ='Q9-Validation'!C133 -> 135000 | AS17: ='Q10-Validation'!C133 -> 135000 | AT17: ='Q11-Validation'!C133 -> 135000 | AU17: ='Q12-Validation'!C133 -> 135000
AI18: A&P Investiments | AJ18: ='Q1'!B101 -> 0 | AK18: ='Q2'!B122 -> 72902.82 | AL18: ='Q3-Validation'!C134 -> 145921.76 | AM18: ='Q4-Validation'!C134 -> 165218.4 | AN18: ='Q5-Validation'!C134 -> 238537.6 | AO18: ='Q6-Validation'!$C$134 -> 190565.01 | AP18: ='Q7-Validation'!C134 -> 292639.19 | AQ18: ='Q8-Validation'!C134 -> 319567.59 | AR18: ='Q9-Validation'!C134 -> 427041.03 | AS18: ='Q10-Validation'!C134 -> 423771.62 | AT18: ='Q11-Validation'!C134 -> 427301.22 | AU18: ='Q12-Validation'!C134 -> 349088.82
AI19: Raw Material Storage Costs | AJ19: ='Q1'!B102 -> 12861.36 | AK19: ='Q2'!B123 -> 13633.042 | AL19: ='Q3-Validation'!C135 -> 14340.416 | AM19: ='Q4-Validation'!C135 -> 13568.735 | AN19: ='Q5-Validation'!C135 -> 11317.997 | AO19: ='Q6-Validation'!$C$135 -> 17491.45 | AP19: ='Q7-Validation'!C135 -> 18756.15 | AQ19: ='Q8-Validation'!C135 -> 20020.85 | AR19: ='Q9-Validation'!C135 -> 20685.354 | AS19: ='Q10-Validation'!C135 -> 21349.858 | AT19: ='Q11-Validation'!C135 -> 16559.001 | AU19: ='Q12-Validation'!C135 -> 1136.0868
AI20: Information Report Purchase | AJ20: ='Q1'!B103 -> 40000 | AK20: ='Q2'!B124 -> 80000 | AL20: ='Q3-Validation'!C136 -> 80000 | AM20: ='Q4-Validation'!C136 -> 80000 | AN20: ='Q5-Validation'!C136 -> 40000 | AO20: ='Q6-Validation'!$C$136 -> 40000 | AP20: ='Q7-Validation'!C136 -> 80000 | AQ20: ='Q8-Validation'!C136 -> 40000 | AR20: ='Q9-Validation'!C136 -> 80000 | AS20: ='Q10-Validation'!C136 -> 0 | AT20: ='Q11-Validation'!C136 -> 80000 | AU20: ='Q12-Validation'!C136 -> 150000
AI21: Freight Costs | AJ21: ='Q1'!B104 -> 0 | AK21: ='Q2'!B125 -> 23490 | AL21: ='Q3-Validation'!C137 -> 47968 | AM21: ='Q4-Validation'!C137 -> 41370 | AN21: ='Q5-Validation'!C137 -> 61890 | AO21: ='Q6-Validation'!$C$137 -> 36058 | AP21: ='Q7-Validation'!C137 -> 55012 | AQ21: ='Q8-Validation'!C137 -> 38776 | AR21: ='Q9-Validation'!C137 -> 63022 | AS21: ='Q10-Validation'!C137 -> 64144 | AT21: ='Q11-Validation'!C137 -> 76922 | AU21: ='Q12-Validation'!C137 -> 55710
AI22: Loss & Damage | AJ22: ='Q1'!B105 -> 0 | AK22: ='Q2'!B126 -> 0 | AL22: ='Q3-Validation'!C138 -> 0 | AM22: ='Q4-Validation'!C138 -> 0 | AN22: ='Q5-Validation'!C138 -> 0 | AO22: ='Q6-Validation'!$C$138 -> 0 | AP22: ='Q7-Validation'!C138 -> 0 | AQ22: ='Q8-Validation'!C138 -> 0 | AR22: ='Q9-Validation'!C138 -> 0 | AS22: ='Q10-Validation'!C138 -> 0 | AT22: ='Q11-Validation'!C138 -> 0 | AU22: ='Q12-Validation'!C138 -> 0
AI23: Loan Interest | AJ23: ='Q1'!B106 -> 0 | AK23: ='Q2'!B127 -> 0 | AL23: ='Q3-Validation'!C139 -> 24003.38 | AM23: ='Q4-Validation'!C139 -> 40253.36 | AN23: ='Q5-Validation'!C139 -> 116709.02 | AO23: ='Q6-Validation'!$C$139 -> 0 | AP23: ='Q7-Validation'!C139 -> 0 | AQ23: ='Q8-Validation'!C139 -> 0 | AR23: ='Q9-Validation'!C139 -> 0 | AS23: ='Q10-Validation'!C139 -> 0 | AT23: ='Q11-Validation'!C139 -> 0 | AU23: ='Q12-Validation'!C139 -> 0
AI24: Factoring Interest | AJ24: ='Q1'!B107 -> 0 | AK24: ='Q2'!B128 -> 0 | AL24: ='Q3-Validation'!C140 -> 0 | AM24: ='Q4-Validation'!C140 -> 0 | AN24: ='Q5-Validation'!C140 -> 0 | AO24: ='Q6-Validation'!$C$140 -> 0 | AP24: ='Q7-Validation'!C140 -> 0 | AQ24: ='Q8-Validation'!C140 -> 0 | AR24: ='Q9-Validation'!C140 -> 0 | AS24: ='Q10-Validation'!C140 -> 0 | AT24: ='Q11-Validation'!C140 -> 0 | AU24: ='Q12-Validation'!C140 -> 0
AI25: Decision Fine | AJ25: ='Q1'!B108 -> 0 | AK25: ='Q2'!B129 -> 0 | AL25: ='Q3-Validation'!C141 -> 0 | AM25: ='Q4-Validation'!C141 -> 0 | AN25: ='Q5-Validation'!C141 -> 0 | AO25: ='Q6-Validation'!$C$141 -> 0 | AP25: ='Q7-Validation'!C141 -> 0 | AQ25: ='Q8-Validation'!C141 -> 0 | AR25: ='Q9-Validation'!C141 -> 0 | AS25: ='Q10-Validation'!C141 -> 0 | AT25: ='Q11-Validation'!C141 -> 0 | AU25: ='Q12-Validation'!C141 -> 0
AI26: PROFIT & LOSS STATEMENT EXPENSES | AJ26: ='Q1'!B109 -> 706786.36 | AK26: ='Q2'!B130 -> 875115.86 | AL26: ='Q3-Validation'!C142 -> 1053653.6 | AM26: ='Q4-Validation'!C142 -> 1087995.5 | AN26: ='Q5-Validation'!C142 -> 1314654.6 | AO26: ='Q6-Validation'!$C$142 -> 1130314.5 | AP26: ='Q7-Validation'!C142 -> 1876807.3 | AQ26: ='Q8-Validation'!C142 -> 1848764.4 | AR26: ='Q9-Validation'!C142 -> 2029148.4 | AS26: ='Q10-Validation'!C142 -> 1947665.5 | AT26: ='Q11-Validation'!C142 -> 2019182.2 | AU26: ='Q12-Validation'!C142 -> 1974334.9
AI28: (+) Income savings | AJ28: ='Q1'!B111 -> 0 | AK28: ='Q2'!B132 -> 0 | AL28: ='Q3-Validation'!C144 -> 0 | AM28: ='Q4-Validation'!C144 -> 0 | AN28: ='Q5-Validation'!C144 -> 0 | AO28: ='Q6-Validation'!$C$144 -> 0 | AP28: ='Q7-Validation'!C144 -> 0 | AQ28: ='Q8-Validation'!C144 -> 0 | AR28: ='Q9-Validation'!C144 -> 0 | AS28: ='Q10-Validation'!C144 -> 0 | AT28: ='Q11-Validation'!C144 -> 0 | AU28: ='Q12-Validation'!C144 -> 0
AI29: (+) Bonus Value | AJ29: ='Q1'!B112 -> 0 | AK29: ='Q2'!B133 -> 0 | AL29: ='Q3-Validation'!C145 -> 0 | AM29: ='Q4-Validation'!C145 -> 0 | AN29: ='Q5-Validation'!C145 -> 0 | AO29: ='Q6-Validation'!$C$145 -> 0 | AP29: ='Q7-Validation'!C145 -> 0 | AQ29: ='Q8-Validation'!C145 -> 0 | AR29: ='Q9-Validation'!C145 -> 0 | AS29: ='Q10-Validation'!C145 -> 0 | AT29: ='Q11-Validation'!C145 -> 0 | AU29: ='Q12-Validation'!C145 -> 0
AI31: Pretax Income | AJ31: ='Q1'!B114 -> -706786.36 | AK31: ='Q2'!B135 -> -499845.76 | AL31: ='Q3-Validation'!C147 -> -175590.34 | AM31: ='Q4-Validation'!C147 -> -193441.46 | AN31: ='Q5-Validation'!C147 -> 730115.33 | AO31: ='Q6-Validation'!$C$147 -> 427649.74 | AP31: ='Q7-Validation'!C147 -> 382407.45 | AQ31: ='Q8-Validation'!C147 -> -89853.06 | AR31: ='Q9-Validation'!C147 -> 553347.61 | AS31: ='Q10-Validation'!C147 -> 852721.5 | AT31: ='Q11-Validation'!C147 -> 1280437 | AU31: ='Q12-Validation'!C147 -> 363767.96
AI32: (-) IR | AJ32: ='Q1'!B115 -> 0 | AK32: ='Q2'!B136 -> 0 | AL32: ='Q3-Validation'!C148 -> 0 | AM32: ='Q4-Validation'!C148 -> 0 | AN32: ='Q5-Validation'!C148 -> 109517.3 | AO32: ='Q6-Validation'!$C$148 -> 64147.461 | AP32: ='Q7-Validation'!C148 -> 57361.118 | AQ32: ='Q8-Validation'!C148 -> 0 | AR32: ='Q9-Validation'!C148 -> 83002.141 | AS32: ='Q10-Validation'!C148 -> 127908.22 | AT32: ='Q11-Validation'!C148 -> 192065.55 | AU32: ='Q12-Validation'!C148 -> 54565.194
AI33: NET PROFIT / LOSS | AJ33: ='Q1'!B116 -> -706786.36 | AK33: ='Q2'!B137 -> -499845.76 | AL33: ='Q3-Validation'!C149 -> -175590.34 | AM33: ='Q4-Validation'!C149 -> -193441.46 | AN33: ='Q5-Validation'!C149 -> 620598.03 | AO33: ='Q6-Validation'!$C$149 -> 363502.28 | AP33: ='Q7-Validation'!C149 -> 325046.33 | AQ33: ='Q8-Validation'!C149 -> -89853.06 | AR33: ='Q9-Validation'!C149 -> 470345.47 | AS33: ='Q10-Validation'!C149 -> 724813.27 | AT33: ='Q11-Validation'!C149 -> 1088371.5 | AU33: ='Q12-Validation'!C149 -> 309202.77
AI35: PREVIOUS QUARTER BALANCE | AJ35: ='Q1'!B118 -> 0 | AK35: ='Q2'!B139 -> -706786.36 | AL35: ='Q3-Validation'!C151 -> -1206632.1 | AM35: ='Q4-Validation'!C151 -> -1382222.5 | AN35: ='Q5-Validation'!C151 -> -1575663.9 | AO35: ='Q6-Validation'!$C$151 -> -955066.65 | AP35: ='Q7-Validation'!C151 -> -591564.37 | AQ35: ='Q8-Validation'!C151 -> -266518.04 | AR35: ='Q9-Validation'!C151 -> -356371.1 | AS35: ='Q10-Validation'!C151 -> 113974.37 | AT35: ='Q11-Validation'!C151 -> 838787.64 | AU35: ='Q12-Validation'!C151 -> 1927159.1
AI36: NET PROFIT / LOSS | AJ36: ='Q1'!B119 -> -706786.36 | AK36: ='Q2'!B140 -> -1206632.1 | AL36: ='Q3-Validation'!C152 -> -1382222.5 | AM36: ='Q4-Validation'!C152 -> -1575663.9 | AN36: ='Q5-Validation'!C152 -> -955065.89 | AO36: ='Q6-Validation'!$C$152 -> 363502.28 | AP36: ='Q7-Validation'!C152 -> 325046.33 | AQ36: ='Q8-Validation'!C152 -> -89853.06 | AR36: ='Q9-Validation'!C152 -> 470345.47 | AS36: ='Q10-Validation'!C152 -> 724813.27 | AT36: ='Q11-Validation'!C152 -> 1088371.5 | AU36: ='Q12-Validation'!C152 -> 309202.77
AI37: Fixed sale variation | AJ37: ='Q1'!B120 -> 0 | AK37: ='Q2'!B141 -> 0 | AL37: ='Q3-Validation'!C153 -> 0 | AM37: ='Q4-Validation'!C153 -> 0 | AN37: ='Q5-Validation'!C153 -> 0 | AO37: ='Q6-Validation'!$C$153 -> 0 | AP37: ='Q7-Validation'!C153 -> 0 | AQ37: ='Q8-Validation'!C153 -> 0 | AR37: ='Q9-Validation'!C153 -> 0 | AS37: ='Q10-Validation'!C153 -> 0 | AT37: ='Q11-Validation'!C153 -> 0 | AU37: ='Q12-Validation'!C153 -> 0
AI38: PROFIT AND LOSS STATEMENT RESULTS | AJ38: ='Q1'!B121 -> -706786.36 | AK38: ='Q2'!B142 -> -1206632.1 | AL38: ='Q3-Validation'!C154 -> -1382222.5 | AM38: ='Q4-Validation'!C154 -> -1575663.9 | AN38: ='Q5-Validation'!C154 -> -955065.89 | AO38: ='Q6-Validation'!$C$154 -> -591564.37 | AP38: ='Q7-Validation'!C154 -> -266518.04 | AQ38: ='Q8-Validation'!C154 -> -356371.1 | AR38: ='Q9-Validation'!C154 -> 113974.37 | AS38: ='Q10-Validation'!C154 -> 838787.64 | AT38: ='Q11-Validation'!C154 -> 1927159.1 | AU38: ='Q12-Validation'!C154 -> 2236361.9
X47: Market Share Per Region - Purchased for Quarter 7
V49: Market Share | W49: Region 1 | X49: Region 2 | Y49: Region 3 | Z49: Region 4
V50: EcoChill | W50: 0.3939 | X50: 0.1154 | Y50: 0.4008 | Z50: 0.073
V51: EcoBreeze | W51: 0.3509 | X51: 0.3178 | Y51: 0.0526 | Z51: 0.5861
V52: Loll | W52: 0.2121 | X52: 0.3388 | Y52: 0.3266 | Z52: 0.2835
V53: NorthBreeze | W53: 0.043 | X53: 0.2279 | Y53: =1-SUM(Y50:Y52) -> 0.22 | Z53: 0.0574
X92: Market Share Per Region - Purchased for Quarter 11
V94: Market Share | W94: Region 1 | X94: Region 2 | Y94: Region 3 | Z94: Region 4
...

Sheet Reference
A1: Packing | B1: Plastic | C1: Motor & Cooling | D1: Electric
A2: Standard | B2: Plastinjet | C2: Motojister | D2: Chukchuk
A3: Premium | B3: Superplast | C3: Motormaster | D3: ConduiteElec
B4: IPLM | C4: InfinityParts | D4: Proline
C5: Freezpro
A6: Template
A7: Prediction
A8: Validation
A10: COGS
A11: Match
A12: Not Match
A14: Quarter
A15: 1
A16: 2
A17: 3
A18: 4
A19: 5
A20: 6
A21: 7
A22: 8
A23: 9
A24: 10
A25: 11
A26: 12
A28: Conservative
A29: Maximum Capacity
A31: Overtime
A32: Regular Hour

Sheet Information-Working
L2: 1 | M2: 2 | N2: 3 | O2: 4
K3: Q2
K4: EcoBreeze | L4: 1499 | M4: 1399 | N4: 1399 | O4: 1499
G5: Total | H5: conv | K5: EcoChill | L5: 1303 | N5: 1273
B6: Demand for Q2 spring | C6: 1344 | D6: 912 | E6: 1008 | F6: 1536 | G6: =SUM(C6:F6) -> 4800 | K6: LOLL | L6: 499 | M6: 469.99 | N6: 469.99 | O6: 499
B7: planned | C7: 150 | D7: 206 | E7: 100 | F7: 650 | G7: =SUM(C7:F7) -> 1106 | K7: NorthBreeze | L7: 999.99 | M7: 999.99 | N7: 949.99 | O7: 999.99
B8: sold | C8: 50 | D8: 103 | E8: 66 | F8: 325 | G8: =SUM(C8:F8) -> 544 | H8: =G8/G7 -> 0.49186257
B9: Conversion | C9: =C8/C7 -> 0.33333333 | D9: =D8/D7 -> 0.5 | E9: =E8/E7 -> 0.66 | F9: =F8/F7 -> 0.5 | G9: =G8/G7 -> 0.49186257 | K9: Average(EquallyPerInc.) | L9: =AVERAGE(L5:L7) -> 933.99667 | M9: =AVERAGE(M5:M7) -> 734.99 | N9: =AVERAGE(N5:N7) -> 897.66 | O9: =AVERAGE(O5:O7) -> 749.495
K10: UpperBound | L10: =L9*(1.3) -> 1214.1957 | M10: =M9*(1.3) -> 955.487 | N10: =N9*(1.3) -> 1166.958 | O10: =O9*(1.3) -> 974.3435 | S10: Conversion | T10: Variance | U10: Predicted variance
K11: LowerBound | L11: =L9*0.7 -> 653.79767 | M11: =M9*0.7 -> 514.493 | N11: =N9*0.7 -> 628.362 | O11: =O9*0.7 -> 524.6465 | R11: Q2 | S11: 0.33 | T11: 0.6 | U11: =-14.133*T11^4+28.203*T11^3-17.515*T11^2+2.9985*T11+0.704 -> 0.4579112
K12: % HigherThanUB | L12: =(L4-L10)/L10 -> 0.23456214 | M12: =(M4-M10)/M10 -> 0.46417481 | N12: =(N4-N10)/N10 -> 0.19884349 | O12: =(O4-O10)/O10 -> 0.5384718 | S12: 0.5 | T12: 0.9 | U12: =-14.133*T12^4+28.203*T12^3-17.515*T12^2+2.9985*T12+0.704 -> 0.5028257
K13: %HigherThanAverage | L13: =(L4-L9)/L9 -> 0.60493078 | M13: =(M4-M9)/M9 -> 0.90342726 | N13: =(N4-N9)/N9 -> 0.55849654 | O13: =(O4-O9)/O9 -> 1.0000133 | S13: 0.66 | T13: 0.56 | U13: =-14.133*T13^4+28.203*T13^3-17.515*T13^2+2.9985*T13+0.704 -> 0.45344473
S14: 0.5 | T14: 0.56 | U14: =-14.133*T14^4+28.203*T14^3-17.515*T14^2+2.9985*T14+0.704 -> 0.45344473
K15: Outcome of pricing : we got punished for being higher than 30% of the average market price. | R15: Q4 | S15: 0.51 | T15: 0.36 | U15: =-14.133*T15^4+28.203*T15^3-17.515*T15^2+2.9985*T15+0.704 -> 0.59197504
S16: 0.26 | T16: 0.39 | U16: =-14.133*T16^4+28.203*T16^3-17.515*T16^2+2.9985*T16+0.704 -> 0.55539864
S17: 0.61 | T17: 0.37 | U17: =-14.133*T17^4+28.203*T17^3-17.515*T17^2+2.9985*T17+0.704 -> 0.57933288
L18: 1 | M18: 2 | N18: 3 | O18: 4 | S18: 0.61 | T18: 0.36 | U18: =-14.133*T18^4+28.203*T18^3-17.515*T18^2+2.9985*T18+0.704 -> 0.59197504
B19: Demand in Q3-summer | C19: 1344 | D19: 912 | E19: 1008 | F19: 1536 | G19: =SUM(C19:F19) -> 4800 | K19: Q3 | R19: Q5 | S19: 0.91 | T19: 0.23 | U19: =-14.133*T19^4+28.203*T19^3-17.515*T19^2+2.9985*T19+0.704 -> 0.77070747
B20: planned | C20: 112 | D20: 300 | E20: 400 | F20: 900 | G20: =112+300+400+900 -> 1712 | K20: EcoBreeze | L20: 1699 | M20: 1699 | N20: 1649 | O20: 1699 | S20: 0.93 | T20: 0.04 | U20: =-14.133*T20^4+28.203*T20^3-17.515*T20^2+2.9985*T20+0.704 -> 0.79768481
B21: sold | C21: 99 | D21: 216 | E21: 207 | F21: 616 | G21: 1138 | H21: =G21/G20 -> 0.66471963 | S21: 0.73 | T21: 0.25 | U21: =-14.133*T21^4+28.203*T21^3-17.515*T21^2+2.9985*T21+0.704 -> 0.74440234
B22: Conversion | C22: =C21/C20 -> 0.88392857 | D22: =D21/D20 -> 0.72 | E22: =E21/E20 -> 0.5175 | F22: =F21/F20 -> 0.68444444 | G22: =G21/G20 -> 0.66471963 | S22: 0.98 | T22: 0.21 | U22: =-14.133*T22^4+28.203*T22^3-17.515*T22^2+2.9985*T22+0.704 -> 0.79497548
B23: Demand in Q4 -fall | C23: 1142 | D23: 775 | E23: 857 | F23: 1306 | G23: =SUM(C23:F23) -> 4080 | L23: 1 | M23: 2 | N23: 3 | O23: 4 | R23: Q6 | S23: 0.92 | T23: 0.22 | U23: =-14.133*T23^4+28.203*T23^3-17.515*T23^2+2.9985*T23+0.704 -> 0.78314214
B24: planned | C24: 414 | D24: 300 | E24: 200 | F24: 800 | G24: =SUM(C24:F24) -> 1714 | H24: 0.52 | K24: Q4 | S24: 0.92 | T24: 0.04 | U24: =-14.133*T24^4+28.203*T24^3-17.515*T24^2+2.9985*T24+0.704 -> 0.79768481
B25: sold | C25: 210 | D25: 79 | E25: 121 | F25: 485 | G25: =SUM(C25:F25) -> 895 | K25: EcoBreeze | L25: 1890 | M25: 1890 | N25: 1845 | O25: 1890 | S25: 0.46 | T25: 0.23 | U25: =-14.133*T25^4+28.203*T25^3-17.515*T25^2+2.9985*T25+0.704 -> 0.77070747
B26: Conversion | C26: =C25/C24 -> 0.50724638 | D26: =D25/D24 -> 0.26333333 | E26: =E25/E24 -> 0.605 | F26: =F25/F24 -> 0.60625 | G26: =G25/G24 -> 0.52217036 | K26: EcoChill | L26: 1179.98 | M26: 1179.98 | N26: 1149.98 | O26: 1189.98 | S26: 0.92 | T26: 0.2 | U26: =-14.133*T26^4+28.203*T26^3-17.515*T26^2+2.9985*T26+0.704 -> 0.8061112
K27: LOLL | L27: 1550 | M27: 1499 | N27: 1499 | O27: 1550 | R27: Q7 | S27: 0.82 | T27: 0.25 | U27: =-14.133*T27^4+28.203*T27^3-17.515*T27^2+2.9985*T27+0.704 -> 0.74440234
K28: NorthBreeze | L28: 1429 | M28: 1399 | N28: 1379 | O28: 1423.99 | S28: 0.85 | T28: 0.06 | U28: =-14.133*T28^4+28.203*T28^3-17.515*T28^2+2.9985*T28+0.704 -> 0.82676468
B29: My reasoning is that we need to increase publicity index in each area to get the highest conversion | S29: 0.91 | T29: 0.25 | U29: =-14.133*T29^4+28.203*T29^3-17.515*T29^2+2.9985*T29+0.704 -> 0.74440234
K30: Average(EquallyPerInc.) | L30: =AVERAGE(L26:L28) -> 1386.3267 | M30: =AVERAGE(M26:M28) -> 1359.3267 | N30: =AVERAGE(N26:N28) -> 1342.66 | O30: =AVERAGE(O26:O28) -> 1387.99 | S30: 0.92 | T30: 0.23 | U30: =-14.133*T30^4+28.203*T30^3-17.515*T30^2+2.9985*T30+0.704 -> 0.77070747
B31: My reasoning is that we need to double the intended planned sales to get the number we want in each area | K31: UpperBound | L31: =L30*(1.3) -> 1802.2247 | M31: =M30*(1.3) -> 1767.1247 | N31: =N30*(1.3) -> 1745.458 | O31: =O30*(1.3) -> 1804.387 | R31: Q8 | S31: 0.68 | T31: 0.28 | U31: =-14.133*T31^4+28.203*T31^3-17.515*T31^2+2.9985*T31+0.704 -> 0.70264692
K32: LowerBound | L32: =L30*0.7 -> 970.42867 | M32: =M30*0.7 -> 951.52867 | N32: =N30*0.7 -> 939.862 | O32: =O30*0.7 -> 971.593 | S32: 0.51 | T32: 0.09 | U32: =-14.133*T32^4+28.203*T32^3-17.515*T32^2+2.9985*T32+0.704 -> 0.85162622
K33: % HigherThanUB | L33: =(L25-L31)/L31 -> 0.04870388 | M33: =(M25-M31)/M31 -> 0.069534049 | N33: =(N25-N31)/N31 -> 0.057029158 | O33: =(O25-O31)/O31 -> 0.047447139 | S33: 0.63 | T33: 0.3 | U33: =-14.133*T33^4+28.203*T33^3-17.515*T33^2+2.9985*T33+0.704 -> 0.6742037
K34: %HigherThanAverage | L34: =(L25-L30)/L30 -> 0.36331504 | M34: =(M25-M30)/M30 -> 0.39039426 | N34: =(N25-N30)/N30 -> 0.37413791 | O34: =(O25-O30)/O30 -> 0.36168128 | S34: 0.64 | T34: 0.27 | U34: =-14.133*T34^4+28.203*T34^3-17.515*T34^2+2.9985*T34+0.704 -> 0.71676259 | W34: Conversion Optimization
R35: Q9 | S35: 0.78 | T35: 0.14 | U35: =-14.133*T35^4+28.203*T35^3-17.515*T35^2+2.9985*T35+0.704 -> 0.8524557 | X35: variance
L36: Still above the 30%: Try to be more conservative | S36: 0.81 | T36: 0.08 | U36: =-14.133*T36^4+28.203*T36^3-17.515*T36^2+2.9985*T36+0.704 -> 0.84564505 | W36: Optimal solution | X36: 0.11516998
S37: 0.81 | T37: 0.17 | U37: =-14.133*T37^4+28.203*T37^3-17.515*T37^2+2.9985*T37+0.704 -> 0.83431882
S38: 0.77 | T38: 0.14 | U38: =-14.133*T38^4+28.203*T38^3-17.515*T38^2+2.9985*T38+0.704 -> 0.8524557
L39: 1 | M39: 2 | N39: 3 | O39: 4 | R39: Q11 | S39: 0.79 | T39: 0.2 | U39: =-14.133*T39^4+28.203*T39^3-17.515*T39^2+2.9985*T39+0.704 -> 0.8061112 | W39: objective function-conversion | Y39: =-14.133*X36^4+28.203*X36^3-17.515*X36^2+2.9985*X36+0.704 -> 0.85761325
K40: Q5 | S40: 0.84 | T40: 0.1 | U40: =-14.133*T40^4+28.203*T40^3-17.515*T40^2+2.9985*T40+0.704 -> 0.8554897
K41: EcoBreeze | L41: 2450 | M41: 1899 | N41: 2450 | O41: 2450 | S41: 0.84 | T41: 0.22 | U41: =-14.133*T41^4+28.203*T41^3-17.515*T41^2+2.9985*T41+0.704 -> 0.78314214
...

Sheet Pricing-Working
M1: Quarter | N1: 2
A2: Planned to sell unit | B2: ='Input_Q9-Predict'!C28 -> 1335 | C2: 222.91667 | D2: Grey part is the price example of the cheapest raw material | I2: DL | J2: 222.91667 | K2: 222.91667 | M2: Sales Income | N2: 798556
C3: 414.25 | I3: RM | J3: 572 | K3: 414.25 | M3: COGS | N3: 423285.9
A4: Variable cost per unit | B4: =('Q9-Predict'!C124)/B2 -> 1083.6631 | C4: =SUM(C2:C3) -> 637.16667 | I4: total before tax | J4: =SUM(J2:J3) -> 794.91667 | K4: =SUM(K2:K3) -> 637.16667 | M4: Gross Profit and Loss | N4: 375270.1
A5: total fixed cost | B5: =('Q9-Predict'!H125)/B2 -> 1437.5479 | C5: =C4*1.125 -> 716.8125 | H5: 0.2 | I5: add profit | J5: =(1+$H$5)*J4 -> 953.9 | K5: =(1+$H$5)*K4 -> 764.6
A6: planned production | C6: =C5*1.2 -> 860.175 | H6: 0.125 | I6: tax | J6: =J5*(1+$H$6) -> 1073.1375 | K6: =K5*(1+$H$6) -> 860.175 | M6: Production Fixed Cost | N6: 280000
M7: Salaries | N7: 272500
A8: Method | B8: Cost plus pricing | M8: Training Investments | N8: 30000
A9: Full cost | B9: `Variable cost per unit+ (Fixed costs/expected units) | M9: Fringe Benefits Investments | N9: 53590
A10: Breakeven Price | B10: =B4+B5 -> 2521.2109 | M10: CSR. Investments | N10: 4000
A11: Add markup | B11: 1.1 | C11: 1.2 | D11: 1.3 | E11: 1.4 | F11: 1.5 | M11: Profit Sharing Payment | N11: 0
A12: Selling price | B12: =$B$10*B11 -> 2773.332 | C12: =$B$10*C11 -> 3025.4531 | D12: =$B$10*D11 -> 3277.5742 | E12: =$B$10*E11 -> 3529.6953 | F12: =$B$10*F11 -> 3781.8164 | M12: Research & Development | N12: 45000
A13: CM | B13: =B12-$B$10 -> 252.12109 | C13: =C12-$B$10 -> 504.24218 | D13: =D12-$B$10 -> 756.36327 | E13: =E12-$B$10 -> 1008.4844 | F13: =F12-$B$10 -> 1260.6055 | M13: A&P Investiments | N13: 72902.82
A14: CM Ratio | B14: =B13/B12 -> 0.090909091 | C14: =C13/C12 -> 0.16666667 | D14: =D13/D12 -> 0.23076923 | E14: =E13/E12 -> 0.28571429 | F14: =F13/F12 -> 0.33333333 | M14: Raw Material Storage Costs | N14: 13633.042
A15: Breakeven Sales | B15: =(SUM($N$7+$N$8+$N$6+$N$9+$N$10+$N$12+$N$13+$N$14+$N$15+$N$16))/'Pricing-Working'!B14 -> 9626274.5 | C15: =(SUM($N$7+$N$8+$N$6+$N$9+$N$10+$N$12+$N$13+$N$14+$N$15+$N$16))/'Pricing-Working'!C14 -> 5250695.2 | D15: =(SUM($N$7+$N$8+$N$6+$N$9+$N$10+$N$12+$N$13+$N$14+$N$15+$N$16))/'Pricing-Working'!D14 -> 3792168.7 | E15: =(SUM($N$7+$N$8+$N$6+$N$9+$N$10+$N$12+$N$13+$N$14+$N$15+$N$16))/'Pricing-Working'!E14 -> 3062905.5 | F15: =(SUM($N$7+$N$8+$N$6+$N$9+$N$10+$N$12+$N$13+$N$14+$N$15+$N$16))/'Pricing-Working'!F14 -> 2625347.6 | M15: Information Report Purchase | N15: 80000
A16: Breakeven units | B16: =(SUM($N$7+$N$8+$N$6+$N$9+$N$10+$N$12+$N$13+$N$14+$N$15+$N$16))/B13 -> 3471.0141 | C16: =(SUM($N$7+$N$8+$N$6+$N$9+$N$10+$N$12+$N$13+$N$14+$N$15+$N$16))/C13 -> 1735.5071 | D16: =(SUM($N$7+$N$8+$N$6+$N$9+$N$10+$N$12+$N$13+$N$14+$N$15+$N$16))/D13 -> 1157.0047 | E16: =(SUM($N$7+$N$8+$N$6+$N$9+$N$10+$N$12+$N$13+$N$14+$N$15+$N$16))/E13 -> 867.75353 | F16: =(SUM($N$7+$N$8+$N$6+$N$9+$N$10+$N$12+$N$13+$N$14+$N$15+$N$16))/F13 -> 694.20282 | M16: Freight Costs | N16: 23490
M17: Loss & Damage | N17: 0
M18: Loan Interest | N18: 0
M19: Factoring Interest | N19: 0
M20: Decision Fine | N20: 0
M21: PROFIT & LOSS STATEMENT EXPENSES | N21: 875115.86
M23: (+) Income savings | N23: 0
M24: (+) Bonus Value | N24: 0
M26: Pretax Income | N26: -499845.76
M27: (-) IR | N27: 0
M28: NET PROFIT / LOSS | N28: -499845.76
M30: PREVIOUS QUARTER BALANCE | N30: -706786.36
M31: NET PROFIT / LOSS | N31: -1206632.1
... M33: PROFIT AND LOSS STATEMENT RESULTS | N33: -1206632.1

Sheet Data_Price
A2: Q2 Price | G2: Q4 Price | M2: Q5 Price | S2: Q6 Price | Y2: Q7 Price | AE2: Q8 Price | AK2: Q9 Price | AQ2: Q11 Price | AW2: Q12 Price
A3: Region | B3: 1 | C3: 2 | D3: 3 | E3: 4 | G3: Region | H3: 1 | I3: 2 | J3: 3 | K3: 4 | M3: Region | N3: 1 | O3: 2 | P3: 3 | Q3: 4 | S3: Region | T3: 1 | U3: 2 | V3: 3 | W3: 4 | Y3: Region | Z3: 1 | AA3: 2 | AB3: 3 | AC3: 4 | AE3: Region | AF3: 1 | AG3: 2 | AH3: 3 | AI3: 4 | AK3: Region | AL3: 1 | AM3: 2 | AN3: 3 | AO3: 4 | AQ3: Region | AR3: 1 | AS3: 2 | AT3: 3 | AU3: 4 | AW3: Region | AX3: 1 | AY3: 2 | AZ3: 3 | BA3: 4
A4: EcoBreeze | B4: 1499 | C4: 1399 | D4: 1399 | E4: 1499 | G4: EcoBreeze | H4: 1890 | I4: 1890 | J4: 1845 | K4: 1890 | M4: EcoBreeze | N4: 2450 | O4: 1899 | P4: 2450 | Q4: 2450 | S4: EcoBreeze | T4: 2799 | U4: 2199 | V4: 2799 | W4: 2799 | Y4: EcoBreeze | Z4: 2899 | AA4: 2399 | AB4: 2899 | AC4: 2899 | AE4: EcoBreeze | AF4: 2999 | AG4: 2499 | AH4: 2999 | AI4: 2999 | AK4: EcoBreeze | AL4: 2799 | AM4: 2599 | AN4: 2799 | AO4: 2799 | AQ4: EcoBreeze | AR4: 2899 | AS4: 2599 | AT4: 2899 | AU4: 2899 | AW4: EcoBreeze | AX4: 2899 | AY4: 2599 | AZ4: 2899 | BA4: 2899
A5: EcoChill | B5: 1303 | C5: 0 | D5: 1273 | E5: 0 | G5: EcoChill | H5: 1179.98 | I5: 1179.98 | J5: 1149.98 | K5: 1179.98 | M5: EcoChill | N5: 1500 | O5: 1450 | P5: 1500 | Q5: 1600 | S5: EcoChill | T5: 1999 | U5: 1949 | V5: 1999 | W5: 2099 | Y5: EcoChill | Z5: 2049 | AA5: 1999 | AB5: 2049 | AC5: 2149 | AE5: EcoChill | AF5: 2099 | AG5: 2049 | AH5: 2099 | AI5: 2149 | AK5: EcoChill | AL5: 2149.98 | AM5: 2099 | AN5: 2149 | AO5: 2199 | AQ5: EcoChill | AR5: 2249.98 | AS5: 2199.98 | AT5: 2249.98 | AU5: 2299.98 | AW5: EcoChill | AX5: 2050 | AY5: 2000 | AZ5: 2050 | BA5: 2100
A6: LOLL | B6: 499.99 | C6: 469.99 | D6: 469.99 | E6: 499.99 | G6: LOLL | H6: 1550 | I6: 1499 | J6: 1499 | K6: 1550 | M6: LOLL | N6: 2099 | O6: 1999 | P6: 1999 | Q6: 2099 | S6: LOLL | T6: 2099 | U6: 1999 | V6: 1999 | W6: 2099 | Y6: LOLL | Z6: 2299 | AA6: 2199 | AB6: 2299 | AC6: 2299 | AE6: LOLL | AF6: 2699 | AG6: 2599 | AH6: 2599 | AI6: 2699 | AK6: LOLL | AL6: 2799 | AM6: 2699 | AN6: 2699 | AO6: 2799 | AQ6: LOLL | AR6: 2399 | AS6: 2299 | AT6: 2299 | AU6: 2399 | AW6: LOLL | AX6: 2399 | AY6: 2299 | AZ6: 2299 | BA6: 2399
A7: NorthBreeze | B7: 999.99 | C7: 999.99 | D7: 949.99 | E7: 999.99 | G7: NorthBreeze | H7: 1429.99 | I7: 1399 | J7: 1379.99 | K7: 1429.99 | M7: NorthBreeze | N7: 1949 | O7: 1949 | P7: 1899 | Q7: 1949 | S7: NorthBreeze | T7: 2299 | U7: 2299 | V7: 2269 | W7: 2299 | Y7: NorthBreeze | Z7: 2599 | AA7: 2599 | AB7: 2599 | AC7: 2599 | AE7: NorthBreeze | AF7: 2249 | AG7: 2249 | AH7: 2229 | AI7: 2249 | AK7: NorthBreeze | AL7: 2399 | AM7: 2399 | AN7: 2359 | AO7: 2399 | AQ7: NorthBreeze | AR7: 2579 | AS7: 2579 | AT7: 2549 | AU7: 2579 | AW7: NorthBreeze | AX7: 2799 | AY7: 2799 | AZ7: 2799 | BA7: 2799
A23: EcoChill in Region 1 and 3

Sheet Data_Sales
B2: Sales
B3: Region\Quarter | C3: 1 | D3: 2 | E3: 3 | F3: 4 | G3: 5 | H3: 6 | I3: 7 | J3: 8 | K3: 9 | L3: 10 | M3: 11 | N3: 12
B4: 1 | C4: 0 | D4: 50 | E4: 99 | F4: 210 | G4: 292 | H4: 150 | I4: 359 | J4: 264 | K4: 427 | L4: 484 | M4: 577 | N4: 403
B5: 2 | C5: 0 | D5: 103 | E5: 216 | F5: 79 | G5: 297 | H5: 301 | I5: 212 | J5: 198 | K5: 271 | L5: 302 | M5: 327 | N5: 210
B6: 3 | C6: 0 | D6: 66 | E6: 207 | F6: 121 | G6: 117 | H6: 25 | I6: 39 | J6: 50 | K6: 48 | L6: 151 | M6: 57 | N6: 40
B7: 4 | C7: 0 | D7: 325 | E7: 616 | F7: 485 | G7: 785 | H7: 501 | I7: 674 | J7: 452 | K7: 759 | L7: 668 | M7: 889 | N7: 655
B8: Freight Cost | C8: 0 | D8: 23490 | E8: 47968 | F8: 41370 | G8: 61890 | H8: 36058 | I8: 55012 | J8: 38776 | K8: 63022 | L8: 64144 | M8: 76922 | N8: 55710
D10: =SUM(D4:D7) -> 544 | E10: =SUM(E4:E7) -> 1138 | F10: =SUM(F4:F7) -> 895 | G10: =SUM(G4:G7) -> 1491 | H10: =SUM(H4:H7) -> 977 | I10: =SUM(I4:I7) -> 1284 | J10: =SUM(J4:J7) -> 964 | K10: =SUM(K4:K7) -> 1505
B14: Demand
B15: Region\Quarter | C15: 1 | D15: 2 | E15: 3 | F15: 4 | G15: 5 | H15: 6 | I15: 7 | J15: 8 | K15: 9 | L15: 10 | M15: 11 | N15: 12
B16: 1 | C16: 0 | D16: 1344 | E16: 1142 | F16: 941
B17: 2 | C17: 0 | D17: 912 | E17: 775 | F17: 638
B18: 3 | C18: 0 | D18: 1008 | E18: 857 | F18: 706
B19: 4 | C19: 0 | D19: 1536 | E19: 1306 | F19: 1075
B21: Market Share
B22: Region\Quarter | C22: 1 | D22: 2 | E22: 3 | F22: 4 | G22: 5 | H22: 6 | I22: 7 | J22: 8 | K22: 9 | L22: 10 | M22: 11 | N22: 12
B23: 1 | C23: 0 | E23: 0.1134 | K23: 0.3544
B24: 2 | C24: 0 | E24: 0.3501 | K24: 0.3329
B25: 3 | C25: 0 | E25: 0.3103 | K25: 0.0536
B26: 4 | C26: 0 | E26: 0.5833 | K26: 0.5524

Sheet Data_CashFlows
A2: Cash Flows | B2: 1 | C2: 2 | D2: 3 | E2: 4 | F2: 5 | G2: 6 | H2: 7 | I2: 8 | J2: 9 | K2: 10 | L2: 11 | M2: 12
A3: Initial Balance | B3: 3200000 | C3: 437085.64 | D3: 100000 | E3: 100000 | F3: 100000 | G3: 214828.04 | H3: 348702.4 | I3: 592772.49 | J3: 215682.39 | K3: 660900.91 | L3: 1412002.7 | M3: 2884721.7
A5: Cash (+) | C5: 798556 | D5: 1923112 | E5: 1686105 | F5: 3489303 | G5: 2554023 | H5: 3616316 | I5: 2792036 | J5: 4158295 | K5: 4562295 | L5: 5265050 | M5: 3728892
A6: Trade Note Received | B6: 0 | C6: 0 | D6: 0 | E6: 0 | F6: 0 | G6: 0 | H6: 0 | I6: 0 | J6: 0 | K6: 0 | L6: 0 | M6: 0
A7: Factoring Amount | B7: 0 | C7: 0 | D7: 0 | E7: 0 | F7: 0 | G7: 0 | H7: 0 | I7: 0 | J7: 0 | K7: 0 | L7: 0 | M7: 0
A8: Borrowed Loan | B8: 0 | C8: 310000 | D8: 300000 | E8: 0 | F8: 0 | G8: 0 | H8: 0 | I8: 0 | J8: 0 | K8: 0 | L8: 0 | M8: 0
A9: Redemptions of Investment | B9: 0 | C9: 0 | D9: 0 | E9: 0 | F9: 0 | G9: 0 | H9: 0 | I9: 0 | J9: 0 | K9: 0 | L9: 0 | M9: 0
A10: Machinery Downgrade (Sell) | B10: 0 | C10: 0 | D10: 0 | E10: 0 | F10: 0 | G10: 0 | H10: 0 | I10: 0 | J10: 0 | K10: 0 | L10: 0 | M10: 0
A11: Bonus Amount | B11: 0 | C11: 0 | D11: 0 | E11: 0 | F11: 0 | G11: 0 | H11: 0 | I11: 0 | J11: 0 | K11: 0 | L11: 0 | M11: 0
A12: TOTAL INCOME (INC LOAN) | B12: 0 | C12: =SUM(C5:C11)+C3 -> 1545641.6 | D12: =SUM(D5:D11) +D3 -> 2323112 | E12: =SUM(E5:E11) +E3 -> 1786105 | F12: =SUM(F5:F11) +F3 -> 3589303 | G12: =SUM(G5:G11) +G3 -> 2768851 | H12: 3616316 | I12: 2792036 | J12: 4158295 | K12: 4562295 | L12: 5265050 | M12: 3728892
A14: Quarter Expenses (-) | B14: 706786.36 | C14: 875115.86 | D14: 1053653.6 | E14: 1087995.5 | F14: 1314655.5 | G14: 1130314.5 | H14: 1876807.3 | I14: 1848764.4 | J14: 2029148.4 | K14: 1947665.5 | L14: 2019182.2 | M14: 1974334.9
A15: Machinery Acquisition | B15: 1500000 | C15: 0 | D15: 0 | E15: 0 | F15: 0 | G15: 0 | H15: 0 | I15: 0 | J15: 0 | K15: 0 | L15: 0 | M15: 0
A16: Variable Cost | B16: 0 | C16: 131761.74 | D16: 435205.96 | E16: 311929.42 | F16: 645521.06 | G16: 472494.27 | H16: 669018.45 | I16: 516526.66 | J16: 769284.56 | K16: 901804.57 | L16: 974034.26 | M16: 689845.01
A17: Income Tax Amount | B17: 0 | C17: 0 | D17: 0 | E17: 0 | F17: 109517.16 | G17: 64147.46 | H17: 57361.12 | I17: 0 | J17: 83002.14 | K17: 127908.23 | L17: 192065.55 | M17: 54565.19
A18: Raw Material Purchase | B18: 556128 | C18: 599598 | D18: 643068 | E18: 579113.28 | F18: 332198.55 | G18: 753192.45 | H18: 769059 | I18: 803835 | J18: 831641.4 | K18: 833814.9 | L18: 607049.04 | M18: 95126.85
A19: Loan Payments | B19: 0 | C19: 0 | D19: 470833.96 | E19: 679649.48 | F19: 972582.67 | G19: 0 | H19: 0 | I19: 0 | J19: 0 | K19: 0 | L19: 0 | M19: 0
A20: Savings | B20: 0 | C20: 0 | D20: 0 | E20: 0 | F20: 0 | G20: 0 | H20: 0 | I20: 0 | J20: 0 | K20: 0 | L20: 0 | M20: 0
A21: Decision Fine | B21: 0 | C21: 0 | D21: 0 | E21: 0 | F21: 0 | G21: 0 | H21: 0 | I21: 0 | J21: 0 | K21: 0 | L21: 0 | M21: 0
A22: TOTAL PAYMENT | B22: =SUM(B14:B21) -> 2762914.4 | C22: =SUM(C14:C21) -> 1606475.6 | D22: =SUM(D14:D21) -> 2602761.5 | E22: =SUM(E14:E21) -> 2658687.7 | F22: =SUM(F14:F21) -> 3374475 | G22: =SUM(G14:G21) -> 2420148.6 | H22: 3372245.9 | I22: 3169126.1 | J22: 3713076.5 | K22: 3811193.2 | L22: 3792331.1 | M22: 2813872
A24: Quarter Final Balance | B24: =B3-B22 -> 437085.64 | C24: =C12-C22 -> -60833.96 | D24: =D12-D22 -> -279649.48 | E24: =E12-E22 -> -872582.67 | F24: =F12-F22 -> 214828.04 | G24: =G12-G22 -> 348702.4 | H24: 592772.49 | I24: 215682.39 | J24: 660900.91 | K24: 1412002.7 | L24: 2884721.7 | M24: 3799741.7
A25: Automatic Loan | B25: 0 | C25: 160833.96 | D25: 379649.48 | E25: 972582.67 | F25: 0 | G25: 0 | H25: 0 | I25: 0 | J25: 0 | K25: 0 | L25: 0 | M25: 0
A26: Adjusted Final Balance | B26: =SUM(B24:B25) -> 437085.64 | C26: =SUM(C24:C25) -> 100000 | D26: =SUM(D24:D25) -> 100000 | E26: =SUM(E24:E25) -> 100000 | F26: =SUM(F24:F25) -> 214828.04 | G26: =SUM(G24:G25) -> 348702.4 | H26: 592772.49 | I26: 215682.39 | J26: 660900.91 | K26: 1412002.7 | L26: 2884721.7 | M26: 3799741.7
A29: Initial Balance | B29: 3200000 | C29: 437085.64 | D29: 100000 | E29: 100000 | F29: 100000 | G29: 214828.04 | H29: =H3 -> 348702.4 | I29: =I3 -> 592772.49 | J29: =J3 -> 215682.39 | K29: =K3 -> 660900.91 | L29: =L3 -> 1412002.7 | M29: =M3 -> 2884721.7
A30: Quarter Final Balance | B30: 437085.64 | C30: -60833.96 | D30: -279649.48 | E30: -872582.67 | F30: 214828.04 | G30: 348702.4 | H30: =H26 -> 592772.49 | I30: =I26 -> 215682.39 | J30: =J26 -> 660900.91 | K30: =K26 -> 1412002.7 | L30: =L26 -> 2884721.7 | M30: =M26 -> 3799741.7

Sheet Data_Stock
A1: Inventory Flow
B2: Category/Quarter | C2: 1 | D2: 2 | E2: 3 | F2: 4 | G2: 5 | H2: 6 | I2: 7 | J2: 8 | K2: 9 | L2: 10 | M2: 11 | N2: 12
B3: Raw Material
B4: Used in Production | C4: 0 | D4: 1128 | E4: 1134 | F4: 1134 | G4: 750 | H4: 924 | I4: 1382 | J4: 1382 | K4: 1498 | L4: 1498 | M4: 1513 | N4: 1439
B5: Purchased | C5: 1200 | D5: 1200 | E5: 1200 | F5: 1062 | G5: 675 | H5: 1500 | I5: 1500 | J5: 1500 | K5: 1560 | L5: 1560 | M5: 1066 | N5: 0
B6: Left | C6: 1200 | D6: =D5+C6-D4 -> 1272 | E6: =E5+D6-E4 -> 1338 | F6: =F5+E6-F4 -> 1266 | G6: 1056 | H6: =G6+H5-H4 -> 1632 | I6: =H6+I5-I4 -> 1750 | J6: =I6+J5-J4 -> 1868 | K6: =J6+K5-K4 -> 1930 | L6: =K6+L5-L4 -> 1992 | M6: =L6+M5-M4 -> 1545 | N6: =M6+N5-N4 -> 106
B7: Finished Goods
B8: Produced | C8: =C4 -> 0 | D8: =D4 -> 1128 | E8: =E4 -> 1134 | F8: =F4 -> 1134 | G8: =G4 -> 750 | H8: =H4 -> 924 | I8: 1382 | J8: 1382 | K8: 1498 | L8: =L4 -> 1498 | M8: 1513 | N8: =N4 -> 1439
B9: Available to sell | C9: 0 | D9: =C11+D8 -> 1128 | E9: =D11+E8 -> 1718 | F9: =E11+F8 -> 1714 | G9: 1569 | H9: =G11+H8 -> 1002 | I9: =H11+I8 -> 1407 | J9: =I11+J8 -> 1505 | K9: =J11+K8 -> 2039 | L9: =K11+L8 -> 2032 | M9: =L11+M8 -> 1940 | N9: =M11+N8 -> 1529
B10: Sold | C10: 0 | D10: 544 | E10: 1138 | F10: 895 | G10: 1491 | H10: 977 | I10: 1284 | J10: 964 | K10: 1505 | L10: 1605 | M10: 1850 | N10: 1308
B11: Left Inventory | C11: =C9-C10 -> 0 | D11: =D9-D10 -> 584 | E11: =E9-E10 -> 580 | F11: =F9-F10 -> 819 | G11: =G9-G10 -> 78 | H11: =H9-H10 -> 25 | I11: =I9-I10 -> 123 | J11: =J9-J10 -> 541 | ... N11: =N9-N10 -> 221
B13: Issue | C13: Loss Material in Q5

Sheet Data_IncomeStatement
A1: Quarter | B1: 1 | C1: 2 | D1: 3 | E1: 4 | F1: 5 | G1: 6 | H1: 7 | I1: 8 | J1: 9 | K1: 10 | L1: 11 | M1: 12
A2: Sales Income | B2: ='Q1'!B90 -> 0 | C2: ='Q2'!B111 -> 798556 | D2: ='Q3-Validation'!C123 -> 1923112 | E2: ='Q4-Validation'!C123 -> 1686105 | F2: 3489303 | G2: ='Q6-Validation'!C123 -> 2554023 | H2: ='Q7-Validation'!C123 -> 3616316 | I2: ='Q8-Validation'!C123 -> 2792036 | J2: ='Q9-Validation'!C123 -> 4158295 | K2: ='Q10-Validation'!C123 -> 4562295 | L2: ='Q11-Validation'!C123 -> 5265050 | M2: ='Q12-Validation'!C123 -> 3728892
A3: COGS | B3: ='Q1'!B91 -> 0 | C3: ='Q2'!B112 -> 423285.9 | D3: ='Q3-Validation'!C124 -> 1045048.8 | E3: ='Q4-Validation'!C124 -> 791550.97 | F3: 1444533.1 | G3: ='Q6-Validation'!C124 -> 996058.8 | H3: ='Q7-Validation'!C124 -> 1357101.2 | I3: ='Q8-Validation'!C124 -> 1033124.6 | J3: ='Q9-Validation'!C124 -> 1575799 | K3: ='Q10-Validation'!C124 -> 1761908 | L3: ='Q11-Validation'!C124 -> 1965430.8 | M3: ='Q12-Validation'!C124 -> 1390789.1
A4: Gross Profit and Loss | B4: ='Q1'!B92 -> 0 | C4: ='Q2'!B113 -> 375270.1 | D4: ='Q3-Validation'!C125 -> 878063.22 | E4: ='Q4-Validation'!C125 -> 894554.03 | F4: 2044769.9 | G4: ='Q6-Validation'!C125 -> 1557964.2 | H4: ='Q7-Validation'!C125 -> 2259214.8 | I4: ='Q8-Validation'!C125 -> 1758911.4 | J4: ='Q9-Validation'!C125 -> 2582496 | K4: ='Q10-Validation'!C125 -> 2800387 | L4: ='Q11-Validation'!C125 -> 3299619.2 | M4: ='Q12-Validation'!C125 -> 2338102.9
G5: ='Q6-Validation'!C126 -> 0 | H5: ='Q7-Validation'!C126 -> 0 | I5: ='Q8-Validation'!C126 -> 0 | J5: ='Q9-Validation'!C126 -> 0 | K5: ='Q10-Validation'!C126 -> 0 | L5: ='Q11-Validation'!C126 -> 0 | M5: ='Q12-Validation'!C126 -> 0
A6: Production Fixed Cost | B6: ='Q1'!B94 -> 280000 | C6: ='Q2'!B115 -> 280000 | D6: ='Q3-Validation'!C127 -> 280000 | E6: ='Q4-Validation'!C127 -> 280000 | F6: 280000 | G6: ='Q6-Validation'!C127 -> 280000 | H6: ='Q7-Validation'!C127 -> 560000 | I6: ='Q8-Validation'!C127 -> 560000 | J6: ='Q9-Validation'!C127 -> 560000 | K6: ='Q10-Validation'!C127 -> 560000 | L6: ='Q11-Validation'!C127 -> 560000 | M6: ='Q12-Validation'!C127 -> 560000
A7: Salaries | B7: ='Q1'!B95 -> 267500 | C7: ='Q2'!B116 -> 272500 | D7: ='Q3-Validation'!C128 -> 282500 | E7: ='Q4-Validation'!C128 -> 287500 | F7: 304200 | G7: ='Q6-Validation'!C128 -> 304200 | H7: ='Q7-Validation'!C128 -> 608400 | I7: ='Q8-Validation'!C128 -> 608400 | J7: ='Q9-Validation'!C128 -> 608400 | K7: ='Q10-Validation'!C128 -> 608400 | L7: ='Q11-Validation'!C128 -> 608400 | M7: ='Q12-Validation'!C128 -> 608400
A8: Training Investments | B8: ='Q1'!B96 -> 20000 | C8: ='Q2'!B117 -> 30000 | D8: ='Q3-Validation'!C129 -> 40000 | E8: ='Q4-Validation'!C129 -> 40000 | F8: 70000 | G8: ='Q6-Validation'!C129 -> 70000 | H8: ='Q7-Validation'!C129 -> 70000 | I8: ='Q8-Validation'!C129 -> 70000 | J8: ='Q9-Validation'!C129 -> 70000 | K8: ='Q10-Validation'!C129 -> 70000 | L8: ='Q11-Validation'!C129 -> 50000 | M8: ='Q12-Validation'!C129 -> 50000
A9: Fringe Benefits Investments | B9: ='Q1'!B97 -> 52425 | C9: ='Q2'!B118 -> 53590 | D9: ='Q3-Validation'!C130 -> 55920 | E9: ='Q4-Validation'!C130 -> 57085 | F9: 47000 | G9: ='Q6-Validation'!C130 -> 47000 | H9: ='Q7-Validation'!C130 -> 47000 | I9: ='Q8-Validation'!C130 -> 47000 | J9: ='Q9-Validation'!C130 -> 47000 | K9: ='Q10-Validation'!C130 -> 47000 | L9: ='Q11-Validation'!C130 -> 47000 | M9: ='Q12-Validation'!C130 -> 47000
A10: CSR. Investments | B10: ='Q1'!B98 -> 4000 | C10: ='Q2'!B119 -> 4000 | D10: ='Q3-Validation'!C131 -> 8000 | E10: ='Q4-Validation'!C131 -> 8000 | F10: 10000 | G10: ='Q6-Validation'!C131 -> 10000 | H10: ='Q7-Validation'!C131 -> 10000 | I10: ='Q8-Validation'!C131 -> 10000 | J10: ='Q9-Validation'!C131 -> 18000 | K10: ='Q10-Validation'!C131 -> 18000 | L10: ='Q11-Validation'!C131 -> 18000 | M10: ='Q12-Validation'!C131 -> 18000
A11: Profit Sharing Payment | B11: ='Q1'!B99 -> 0 | C11: ='Q2'!B120 -> 0 | D11: ='Q3-Validation'!C132 -> 0 | E11: ='Q4-Validation'!C132 -> 0 | F11: 0 | G11: ='Q6-Validation'!C132 -> 0 | H11: ='Q7-Validation'!C132 -> 0 | I11: ='Q8-Validation'!C132 -> 0 | J11: ='Q9-Validation'!C132 -> 0 | K11: ='Q10-Validation'!C132 -> 0 | L11: ='Q11-Validation'!C132 -> 0 | M11: ='Q12-Validation'!C132 -> 0
A12: Research & Development | B12: ='Q1'!B100 -> 30000 | C12: ='Q2'!B121 -> 45000 | D12: ='Q3-Validation'!C133 -> 75000 | E12: ='Q4-Validation'!C133 -> 75000 | F12: 135000 | G12: ='Q6-Validation'!C133 -> 135000 | H12: ='Q7-Validation'!C133 -> 135000 | I12: ='Q8-Validation'!C133 -> 135000 | J12: ='Q9-Validation'!C133 -> 135000 | K12: ='Q10-Validation'!C133 -> 135000 | L12: ='Q11-Validation'!C133 -> 135000 | M12: ='Q12-Validation'!C133 -> 135000
A13: A&P Investiments | B13: ='Q1'!B101 -> 0 | C13: ='Q2'!B122 -> 72902.82 | D13: ='Q3-Validation'!C134 -> 145921.76 | E13: ='Q4-Validation'!C134 -> 165218.4 | F13: 238537.6 | G13: ='Q6-Validation'!C134 -> 190565.01 | H13: ='Q7-Validation'!C134 -> 292639.19 | I13: ='Q8-Validation'!C134 -> 319567.59 | J13: ='Q9-Validation'!C134 -> 427041.03 | K13: ='Q10-Validation'!C134 -> 423771.62 | L13: ='Q11-Validation'!C134 -> 427301.22 | M13: ='Q12-Validation'!C134 -> 349088.82
A14: Raw Material Storage Costs | B14: ='Q1'!B102 -> 12861.36 | C14: ='Q2'!B123 -> 13633.042 | D14: ='Q3-Validation'!C135 -> 14340.416 | E14: ='Q4-Validation'!C135 -> 13568.735 | F14: 11318 | G14: ='Q6-Validation'!C135 -> 17491.45 | H14: ='Q7-Validation'!C135 -> 18756.15 | I14: ='Q8-Validation'!C135 -> 20020.85 | J14: ='Q9-Validation'!C135 -> 20685.354 | K14: ='Q10-Validation'!C135 -> 21349.858 | L14: ='Q11-Validation'!C135 -> 16559.001 | M14: ='Q12-Validation'!C135 -> 1136.0868
A15: Information Report Purchase | B15: ='Q1'!B103 -> 40000 | C15: ='Q2'!B124 -> 80000 | D15: ='Q3-Validation'!C136 -> 80000 | E15: ='Q4-Validation'!C136 -> 80000 | F15: 40000 | G15: ='Q6-Validation'!C136 -> 40000 | H15: ='Q7-Validation'!C136 -> 80000 | I15: ='Q8-Validation'!C136 -> 40000 | J15: ='Q9-Validation'!C136 -> 80000 | K15: ='Q10-Validation'!C136 -> 0 | L15: ='Q11-Validation'!C136 -> 80000 | M15: ='Q12-Validation'!C136 -> 150000
A16: Freight Costs | B16: ='Q1'!B104 -> 0 | C16: ='Q2'!B125 -> 23490 | D16: ='Q3-Validation'!C137 -> 47968 | E16: ='Q4-Validation'!C137 -> 41370 | F16: 61890 | G16: ='Q6-Validation'!C137 -> 36058 | H16: ='Q7-Validation'!C137 -> 55012 | I16: ='Q8-Validation'!C137 -> 38776 | J16: ='Q9-Validation'!C137 -> 63022 | K16: ='Q10-Validation'!C137 -> 64144 | L16: ='Q11-Validation'!C137 -> 76922 | M16: ='Q12-Validation'!C137 -> 55710
A17: Loss & Damage | B17: ='Q1'!B105 -> 0 | C17: ='Q2'!B126 -> 0 | D17: ='Q3-Validation'!C138 -> 0 | E17: ='Q4-Validation'!C138 -> 0 | F17: 0 | G17: ='Q6-Validation'!C138 -> 0 | H17: ='Q7-Validation'!C138 -> 0 | I17: ='Q8-Validation'!C138 -> 0 | J17: ='Q9-Validation'!C138 -> 0 | K17: ='Q10-Validation'!C138 -> 0 | L17: ='Q11-Validation'!C138 -> 0 | M17: ='Q12-Validation'!C138 -> 0
... A21: PROFIT & LOSS STATEMENT EXPENSES | B21: ='Q1'!B109 -> 706786.36 | C21: ='Q2'!B130 -> 875115.86 | D21: ='Q3-Validation'!C142 -> 1053653.6 | E21: ='Q4-Validation'!C142 -> 1087995.5 | F21: 1314655.5 | G21: ='Q6-Validation'!C142 -> 1130314.5 | H21: ='Q7-Validation'!C142 -> 1876807.3 | I21: ='Q8-Validation'!C142 -> 1848764.4 | J21: ='Q9-Validation'!C142 -> 2029148.4 | K21: ='Q10-Validation'!C142 -> 1947665.5 | L21: ='Q11-Validation'!C142 -> 2019182.2 | M21: ='Q12-Validation'!C142 -> 1974334.9
G22: ='Q6-Validation'!C143 -> 0 | H22: ='Q7-Validation'!C143 -> 0 | I22: ='Q8-Validation'!C143 -> 0 | J22: ='Q9-Validation'!C143 -> 0 | K22: ='Q10-Validation'!C143 -> 0 | L22: ='Q11-Validation'!C143 -> 0 | M22: ='Q12-Validation'!C143 -> 0
A23: (+) Income savings | B23: ='Q1'!B111 -> 0 | C23: ='Q2'!B132 -> 0 | D23: ='Q3-Validation'!C144 -> 0 | E23: ='Q4-Validation'!C144 -> 0 | F23: 0 | G23: ='Q6-Validation'!C144 -> 0 | H23: ='Q7-Validation'!C144 -> 0 | I23: ='Q8-Validation'!C144 -> 0 | J23: ='Q9-Validation'!C144 -> 0 | K23: ='Q10-Validation'!C144 -> 0 | L23: ='Q11-Validation'!C144 -> 0 | M23: ='Q12-Validation'!C144 -> 0
A24: (+) Bonus Value | B24: ='Q1'!B112 -> 0 | C24: ='Q2'!B133 -> 0 | D24: ='Q3-Validation'!C145 -> 0 | E24: ='Q4-Validation'!C145 -> 0 | F24: 0 | G24: ='Q6-Validation'!C145 -> 0 | H24: ='Q7-Validation'!C145 -> 0 | I24: ='Q8-Validation'!C145 -> 0 | J24: ='Q9-Validation'!C145 -> 0 | K24: ='Q10-Validation'!C145 -> 0 | L24: ='Q11-Validation'!C145 -> 0 | M24: ='Q12-Validation'!C145 -> 0
G25: ='Q6-Validation'!C146 -> 0 | H25: ='Q7-Validation'!C146 -> 0 | I25: ='Q8-Validation'!C146 -> 0 | J25: ='Q9-Validation'!C146 -> 0 | K25: ='Q10-Validation'!C146 -> 0 | L25: ='Q11-Validation'!C146 -> 0 | M25: ='Q12-Validation'!C146 -> 0
A26: Pretax Income | B26: ='Q1'!B114 -> -706786.36 | C26: ='Q2'!B135 -> -499845.76 | D26: ='Q3-Validation'!C147 -> -175590.34 | E26: ='Q4-Validation'!C147 -> -193441.46 | F26: 730143.43 | G26: ='Q6-Validation'!C147 -> 427649.74 | H26: ='Q7-Validation'!C147 -> 382407.45 | I26: ='Q8-Validation'!C147 -> -89853.06 | J26: ='Q9-Validation'!C147 -> 553347.61 | K26: ='Q10-Validation'!C147 -> 852721.5 | L26: ='Q11-Validation'!C147 -> 1280437 | M26: ='Q12-Validation'!C147 -> 363767.96
